<?xml version="1.0"?>
<robot xmlns:xacro="http://www.ros.org/wiki/xacro" name="komodo">
	<xacro:property name="M_PI" value="3.1415926535897931" />
	
	<link name="asus_camera_link">
		<inertial>
			<origin rpy="0 0 0" xyz="-0.0187798361475048 -0.000287133366772307 -0.000201032384153296" />
			<mass value="0.150306955527936" />
			<inertia ixx="0.00039928218741962" ixy="-5.34870767194659E-07" ixz="-1.37242873517293E-08" iyy="2.36182089627434E-05" iyz="-8.67618422000016E-09" izz="0.000406064964123578" />
		</inertial>
		<visual>
			<origin rpy="0 0 0" xyz="0.005 0 0" />
			<geometry>
				<mesh filename="package://robotican_komodo/description/meshes/asus_camera_link.STL" />
			</geometry>
			<material name="">
				<color rgba="0.1792156862745098 0.1819607843137255 0.1933333333333333 1" />
			</material>
		</visual>
		<collision>
			<origin rpy="0 0 0" xyz="0 0 0" />
			<geometry>
				<mesh filename="package://robotican_komodo/description/meshes/asus_camera_link.STL" />
			</geometry>
		</collision>
	</link>
	
	<link name="front_camera_link">
		<inertial>
			<origin rpy="0 0 0" xyz="3.63553471578737E-06 0.000213443852909154 -0.00979905092954431" />
			<mass value="0.0346828331927876" />
			<inertia ixx="6.28790547336199E-06" ixy="-2.06834494924545E-09" ixz="1.17994816105049E-09" iyy="6.08020816375924E-06" iyz="3.61787794067701E-08" izz="9.95214453956241E-06" />
		</inertial>
		<visual>
			<origin rpy="-1.57079632649567 1.57079632649567 -1.57079632649567" xyz="0.005 0 0" />
			<geometry>
				<mesh filename="package://robotican_komodo/description/meshes/front_camera_link.STL" />
			</geometry>
			<material name="">
				<color rgba="0.1 0.1 0.1 1" />
			</material>
		</visual>
		<collision>
			<origin rpy="1.57 0 0" xyz="0 0 0" />
			<geometry>
				<mesh filename="package://robotican_komodo/description/meshes/front_camera_link.STL" />
			</geometry>
		</collision>
	</link>
	
	<link name="base_link">
		<inertial>
			<origin rpy="0 0 0" xyz="-0.0205330571995271 4.54409684683429E-05 0.00735986203300292" />
			<mass value="45.0894999160313" />
			<inertia ixx="0.723503030508731" ixy="-46.8485359152423E-05" ixz="-0.0875564429068847" iyy="1.38127064231828" iyz="11.9695110167269E-05" izz="1.94371448739423" />
		</inertial>
		<visual>
			<origin rpy="0 0 0" xyz="0 0 0" />
			<geometry>
				<mesh filename="package://robotican_komodo/description/meshes/base_link.STL" />
			</geometry>
			<material name="">
				<color rgba="0.52941176470588 0.52941176470588 0.52941176470588 1" /> 
			</material>
		</visual>
		<collision>
			<origin rpy="0 0 0" xyz="-0.065 0 0" />
			<geometry>
				<mesh filename="package://robotican_komodo/description/meshes/base_link.STL" />
			</geometry>
		</collision>
  	</link>
  	
	<link name="fl_wheel_link">
		<inertial>
			<origin rpy="0 0 0" xyz="-0.00160662480262744 -2.59228543311729E-06 1.49951351856364E-05" />
			<mass value="3.83427523136739" />
			<inertia ixx="0.0296525525807749" ixy="1.51001277133356E-06" ixz="2.35766660656153E-06" iyy="0.0163749526386264" iyz="1.2254511654214E-06" izz="0.0163720506916083" />
		</inertial>
		<visual>
			<origin rpy="0 0 0" xyz="0 0 0" />
			<geometry>
				<mesh filename="package://robotican_komodo/description/meshes/fl_wheel_link.STL" />
			</geometry>
			<material name="">
				<color rgba="0.15 0.15 0.15 1" />
			</material>
		</visual>
		<collision>
			<origin rpy="0 ${M_PI/2} 0" xyz="0 0 0" />
			<geometry>
				<cylinder length="0.03" radius="0.1311" />
			</geometry>
		</collision>
  	</link>
  		
	<link name="fr_wheel_link">
		<inertial>
			<origin rpy="0 0 0" xyz="-0.00160662478940524 -2.59227836232889E-06 1.49952129885679E-05" />
			<mass value="3.8342752339456" />
			<inertia ixx="0.0296525526023316" ixy="1.51001308635369E-06" ixz="2.3576732629264E-06" iyy="0.0163749526634419" iyz="1.22545882852199E-06" izz="0.0163720506902763" />
		</inertial>
		<visual>
			<origin rpy="0 0 0" xyz="0 0 0" />
			<geometry>
				<mesh filename="package://robotican_komodo/description/meshes/fr_wheel_link.STL" />
			</geometry>
			<material name="">
				<color rgba="0.15 0.15 0.15 1" />
			</material>
		</visual>
		<collision>
			<origin rpy="0 ${M_PI/2} 0" xyz="0 0 0" />
			<geometry>
				<cylinder length="0.03" radius="0.1311" />
			</geometry>
		</collision>
  	</link>
  	
	<link name="rl_wheel_link">
		<inertial>
			<origin rpy="0 0 0" xyz="-0.00160662477936549 -2.59222765522371E-06 1.49952106412736E-05" />
			<mass value="3.83427523542708" />
			<inertia ixx="0.0296525526119397" ixy="1.5100179619978E-06" ixz="2.35767335983606E-06" iyy="0.0163749526769378" iyz="1.22544931791974E-06" izz="0.0163720506885898" />
		</inertial>
		<visual>
			<origin rpy="0 0 0" xyz="0 0 0" />
			<geometry>
				<mesh filename="package://robotican_komodo/description/meshes/rl_wheel_link.STL" />
			</geometry>
			<material name="">
				<color rgba="0.15 0.15 0.15 1" />
			</material>
		</visual>
		<collision>
			<origin rpy="0 ${M_PI/2} 0" xyz="0 0 0" />
			<geometry>
				<cylinder length="0.03" radius="0.1311" />
			</geometry>
		</collision>
  	</link>
  	
	<link name="rr_wheel_link">
		<inertial>
			<origin rpy="0 0 0" xyz="-0.00160662476834383 -2.59238516814309E-06 1.49950507030127E-05" />
			<mass value="3.83427523968864" />
			<inertia ixx="0.0296525526652264" ixy="1.5100019082583E-06" ixz="2.35765651707649E-06" iyy="0.0163749526901628" iyz="1.22544631738128E-06" izz="0.0163720507270359" />
		</inertial>
		<visual>
			<origin rpy="0 0 0" xyz="0 0 0" />
			<geometry>
				<mesh filename="package://robotican_komodo/description/meshes/rr_wheel_link.STL" />
			</geometry>
			<material name="">
				<color rgba="0.15 0.15 0.15 1" />
			</material>
		</visual>
		<collision>
			<origin rpy="0 ${M_PI/2} 0" xyz="0 0 0" />
			<geometry>
				<cylinder length="0.03" radius="0.1311" />
			</geometry>
		</collision>
  	</link>
	
	<link name="laser_link">
		<inertial>
			<origin rpy="0 0 0" xyz="5.67786090348299E-05 -6.35639788811446E-05 -0.0320034700075499" />
			<mass value="0.133672626323353" />
			<inertia ixx="7.01753800311366E-05" ixy="-5.24162580339348E-08" ixz="1.6420597550453E-07" iyy="7.0476938858621E-05" iyz="1.92324838956078E-07" izz="4.61464878783427E-05" />
		</inertial>
		<visual>
			<origin rpy="0 0 ${M_PI}" xyz="0.003 0 0" />
			<geometry>
				<mesh filename="package://robotican_komodo/description/meshes/laser_link.STL" />
			</geometry>
			<material name="">
				<color rgba="0.192156862745098 0.1819607843137255 0.1933333333333333 1" />
			</material>
		</visual>
		<collision>
			<origin rpy="0 0 0" xyz="0 0 0" />
			<geometry>
				<mesh filename="package://robotican_komodo/description/meshes/laser_link.STL" />
			</geometry>
		</collision>
	</link>
	
	<link name="left_urf_link">
		<inertial>
			<origin rpy="0 0 0" xyz="-0.00942258060476561 1.68888278492922E-05 -0.000193183712129175" />
			<mass value="0.00277487854391404" />
			<inertia ixx="1.28314681514111E-07" ixy="-1.54585356342896E-10" ixz="3.11030599725484E-09" iyy="1.18940672500039E-07" iyz="4.35265830364889E-09" izz="1.28434121553121E-07" />
		</inertial>
		<visual>
			<origin rpy="0 0 0" xyz="0 0 0" />
			<geometry>
				<mesh filename="package://robotican_komodo/description/meshes/left_urf_link.STL" />
			</geometry>
			<material name="">
				<color rgba="0.752941176470588 0.752941176470588 0.752941176470588 1" />
			</material>
		</visual>
		<collision>
			<origin rpy="0 0 0" xyz="0 0 0" />
			<geometry>
				<mesh filename="package://robotican_komodo/description/meshes/left_urf_link.STL" />
			</geometry>
		</collision>
	</link>
	
	<link name="rear_urf_link">
		<inertial>
			<origin rpy="0 0 0" xyz="-0.00942258060476558 1.68888278491873E-05 -0.000193183712129189" />
			<mass value="0.0027748785439141" />
			<inertia ixx="1.28314681514116E-07" ixy="-1.54585356343498E-10" ixz="3.1103059972555E-09" iyy="1.18940672500041E-07" iyz="4.35265830364838E-09" izz="1.28434121553125E-07" />
		</inertial>
		<visual>
			<origin rpy="0 0 0" xyz="0 0 0" />
			<geometry>
				<mesh filename="package://robotican_komodo/description/meshes/rear_urf_link.STL" />
			</geometry>
			<material name="">
				<color rgba="0.752941176470588 0.752941176470588 0.752941176470588 1" />
			</material>
		</visual>
		<collision>
			<origin rpy="0 0 0" xyz="0 0 0" />
			<geometry>
				<mesh filename="package://robotican_komodo/description/meshes/rear_urf_link.STL" />
			</geometry>
		</collision>
	</link>
	
	<link name="right_urf_link">
		<inertial>
			<origin rpy="0 0 0" xyz="-0.00942258060476561 1.68888278493408E-05 -0.000193183712129202" />
			<mass value="0.00277487854391409" />
			<inertia ixx="1.28314681514115E-07" ixy="-1.54585356342962E-10" ixz="3.11030599725548E-09" iyy="1.18940672500041E-07" iyz="4.3526583036484E-09" izz="1.28434121553124E-07" />
		</inertial>
		<visual>
			<origin rpy="0 0 0" xyz="0 0 0" />
			<geometry>
				<mesh filename="package://robotican_komodo/description/meshes/right_urf_link.STL" />
			</geometry>
			<material name="">
				<color rgba="0.752941176470588 0.752941176470588 0.752941176470588 1" />
			</material>
		</visual>
		<collision>
			<origin rpy="0 0 0" xyz="0 0 0" />
			<geometry>
				<mesh filename="package://robotican_komodo/description/meshes/right_urf_link.STL" />
			</geometry>
		</collision>
	</link>
	
	<link name="sensors_unit_link">
		<inertial>
			<origin rpy="0 0 0" xyz="0.0414414719218708 -0.000373289194023478 0.0507806551833217" />
			<mass value="3.00493541386534" />
			<inertia ixx="0.0317419196615914" ixy="-0.000328957251382255" ixz="-0.0101477531293138" iyy="0.0944166881470797" iyz="2.04069229359132E-05" izz="0.116969738863327" />
		</inertial>
		<visual>
			<origin rpy="0 0 0" xyz="0 0 0" />
			<geometry>
				<mesh filename="package://robotican_komodo/description/meshes/sensors_unit_link.STL" />
			</geometry>
			<material name="">
				<color rgba="0.6509803921568627 0.6537254901960784 0.656078431372549 1" />
			</material>
		</visual>
		<collision>
			<origin rpy="0 0 0" xyz="0 0 0" />
			<geometry>
				<mesh filename="package://robotican_komodo/description/meshes/sensors_unit_link.STL" />
			</geometry>
		</collision>
	</link>
	

	
	<!--         END         -->

	<!-- Load all the joints -->
	
	<joint name="fr_wheel_joint" type="continuous">
    		<origin xyz="0.173999999999995 -0.2009 0" rpy="2.62229105359916E-15 6.9308460464278E-17 1.5707963267949" />
    		<parent link="base_link" />
    		<child link="fr_wheel_link" />
    		<axis xyz="1 0 0" />
  	</joint>
  	
	<joint name="fl_wheel_joint" type="continuous">
    		<origin xyz="0.173999999999995 0.2009 0" rpy="-2.62229105359916E-15 6.93084604642783E-17 -1.5707963267949" />
    		<parent link="base_link" />
    		<child link="fl_wheel_link" />
    		<axis xyz="-1 0 0" />
  	</joint>
  	
	<joint name="rr_wheel_joint" type="continuous">
    		<origin xyz="-0.156000000000005 -0.2009 0" rpy="2.62229105359916E-15 -1.59433090848306E-31 1.5707963267949" />
    		<parent link="base_link" />
    		<child link="rr_wheel_link" />
    		<axis xyz="1 0 0" />
  	</joint>
  	
	<joint name="rl_wheel_joint" type="continuous">
    		<origin xyz="-0.156000000000005 0.2009 0" rpy="-2.62229105359916E-15 -5.57680208627196E-32 -1.5707963267949" />
    		<parent link="base_link" />
    		<child link="rl_wheel_link" />
    		<axis xyz="-1 0 0" />
  	</joint>

	<joint name="left_urf_joint" type="fixed">
    		<origin xyz="-0.0223133326154785 0.137250000000005 0.138508176066688" rpy="-2.73331335606168E-15 1.59433090848306E-31 1.5707963267949" />
    		<parent link="base_link" />
    		<child link="left_urf_link" />
    		<axis xyz="-1 0 0" />
  	</joint>
	
	<joint name="rear_urf_joint" type="fixed">
    		<origin xyz="-0.267499972183238 0 0.107999999999999" rpy="-6.16297582203915E-33 2.73331335606168E-15 3.14159265358979" />
    		<parent link="base_link" />
    		<child link="rear_urf_link" />
    		<axis xyz="-1 0 0" />
  	</joint>


	<joint name="right_urf_joint" type="fixed">
    		<origin xyz="-0.0223133326154785 -0.137249999999995 0.138508176066688" rpy="2.73331335606168E-15 -1.59433090848306E-31 -1.5707963267949" />
    		<parent link="base_link" />
    		<child link="right_urf_link" />
    		<axis xyz="-1 0 0" />
  	</joint>

	<joint name="front_camera_joint" type="fixed">
    		<origin xyz="0.262250027816762 0.0875000000000051 0.100000000000001" rpy="0 0 0" />
    		<parent link="base_link" />
    		<child link="front_camera_link" />
    		<axis xyz="0 0 1" />
  	</joint>

	<joint name="laser_joint" type="fixed">
    		<origin xyz="0.234263427816762 0 0.145827195177237" rpy="-6.93084604642783E-17 -2.62229105359916E-15 5.55111512312578E-17" />
    		<parent link="base_link" />
    		<child link="laser_link" />
    		<axis xyz="0 0 -1" />
  	</joint>
	
	<joint name="asus_camera_joint" type="fixed">
    		<origin xyz="0.262250027816762 0 0.0635000000000008" rpy="-6.93084604642783E-17 -2.62229105359916E-15 5.55111512312578E-17" />
    		<parent link="base_link" />
    		<child link="asus_camera_link" />
    		<axis xyz="-1 0 0" />
  	</joint>
  	
	<joint name="sensors_unit_joint" type="fixed">
    		<origin xyz="-0.00199997218323841 0 0.0835000000000001" rpy="-1.59433090848306E-31 -2.62229105359916E-15 5.55111512312578E-17" />
    		<parent link="base_link" />
    		<child link="sensors_unit_link" />
    		<axis xyz="1 0 0" />
  	</joint>
  	
	<!--         END         -->
</robot>
