<?xml version="1.0"?>
<robot xmlns:xacro="http://www.ros.org/wiki/xacro" name="komodo_with_arm">
	
	<!--    BASE ROBOT     -->
	<xacro:include filename="$(find robotican_description)/armadillo/robots/armadillo_base_urdf.xacro" />
	<!--      END          -->
	
	<!--    ELEV ROBOT     -->
	<xacro:include filename="$(find robotican_description)/armadillo/robots/armadillo_elevator_urdf.xacro" />
	<!--      END          -->
	
	<!--    ELEV ROBOT     -->
	<xacro:include filename="$(find robotican_description)/robot_arms/armadillo_arm_urdf/robots/armadillo_arm_urdf.xacro" />
	<!--      END          -->
	
	<!--    LOAD JOINTS    -->
	<joint name="base_elevator_joint" type="prismatic">
		<origin xyz="-0.1403 0 0.49381" rpy="0 0 0" />
		<parent link="base_link" />
		<child link="base_elevator_link" />
		<axis xyz="0 0 1" />
		<dynamics damping="1000.0" friction="100000.0"/>
		<limit effort="1.765196" velocity="0.1" lower="0.0125" upper="0.4" />
	</joint>
	
	<joint name="base_arm_joint" type="fixed">
		<origin xyz="0.033 0 0.03575" rpy="0 0 0" />
		<parent link="arm_link" />
		<child link="base_arm_link" />
		<axis xyz="0 0 0" />
	</joint>
	
	<!--      END          -->
	
	
</robot>
