<?xml version="1.0"?>
<robot
  name="armadillo_arm_urdf" description="Armadillo robot arm">
  <link
    name="base_arm_link">
    <inertial>
      <origin
        xyz="0.00022998 -5.8526E-11 -0.027818"
        rpy="0 0 0" />
      <mass
        value="0.32416" />
      <inertia
        ixx="0.00045599"
        ixy="1.2992E-13"
        ixz="-4.1813E-06"
        iyy="0.00045553"
        iyz="7.9519E-13"
        izz="0.00014363" />
    </inertial>
    <visual>
      <origin
        xyz="0 0 0"
        rpy="0 0 0" />
      <geometry>
        <mesh
          filename="package://robotican_description/robot_arms/armadillo_arm_urdf/meshes/base_arm_link.STL" />
      </geometry>
      <material
        name="">
        <color
          rgba="0.89804 0.91765 0.92941 1" />
      </material>
    </visual>
    <collision>
      <origin
        xyz="0 0 0"
        rpy="0 0 0" />
      <geometry>
        <mesh
          filename="package://robotican_description/robot_arms/armadillo_arm_urdf/meshes/base_arm_link.STL" />
      </geometry>
    </collision>
  </link>
  <link
    name="rotation1_link">
    <inertial>
      <origin
        xyz="-3.5191E-10 0.0073117 0.037899"
        rpy="0 0 0" />
      <mass
        value="0.35317" />
      <inertia
        ixx="0.00055596"
        ixy="9.2617E-12"
        ixz="9.2232E-12"
        iyy="0.00016945"
        iyz="6.1918E-06"
        izz="0.00055286" />
    </inertial>
    <visual>
      <origin
        xyz="0 0 0"
        rpy="0 0 0" />
      <geometry>
        <mesh
          filename="package://robotican_description/robot_arms/armadillo_arm_urdf/meshes/rotation1_link.STL" />
      </geometry>
      <material
        name="">
        <color
          rgba="0.89804 0.91765 0.92941 1" />
      </material>
    </visual>
    <collision>
      <origin
        xyz="0 0 0"
        rpy="0 0 0" />
      <geometry>
        <mesh
          filename="package://robotican_description/robot_arms/armadillo_arm_urdf/meshes/rotation1_link.STL" />
      </geometry>
    </collision>
  </link>
  <joint
    name="rotation1_joint"
    type="revolute">
    <origin
      xyz="0 0 0.03"
      rpy="0 0 0" />
    <parent
      link="base_arm_link" />
    <child
      link="rotation1_link" />
    <axis
      xyz="0 0 1" />
    <limit
      effort="44.7"
      lower="-1.57"
      upper="1.57"
      velocity="3.455751915" />
  </joint>
  <link
    name="shoulder1_link">
    <inertial>
      <origin
        xyz="0.01628 0.00657 0.20044"
        rpy="0 0 0" />
      <mass
        value="0.52217" />
      <inertia
        ixx="0.0043595"
        ixy="-3.1405E-06"
        ixz="0.00053636"
        iyy="0.0041046"
        iyz="-5.2275E-05"
        izz="0.00081871" />
    </inertial>
    <visual>
      <origin
        xyz="0 0 0"
        rpy="0 0 0" />
      <geometry>
        <mesh
          filename="package://robotican_description/robot_arms/armadillo_arm_urdf/meshes/shoulder1_link.STL" />
      </geometry>
      <material
        name="">
        <color
          rgba="0.75294 0.75294 0.75294 1" />
      </material>
    </visual>
    <collision>
      <origin
        xyz="0 0 0"
        rpy="0 0 0" />
      <geometry>
        <mesh
          filename="package://robotican_description/robot_arms/armadillo_arm_urdf/meshes/shoulder1_link.STL" />
      </geometry>
    </collision>
  </link>
  <joint
    name="shoulder1_joint"
    type="revolute">
    <origin
      xyz="0 0 0.039"
      rpy="0 0 0" />
    <parent
      link="rotation1_link" />
    <child
      link="shoulder1_link" />
    <axis
      xyz="0 1 0" />
    <limit
      effort="44.7"
      lower="0"
      upper="1.57"
      velocity="3.455751915" />
  </joint>
  <link
    name="shoulder2_link">
<inertial>
      <origin
        xyz="0.068154 0.0063088 0.11032"
        rpy="0 0 0" />
      <mass
        value="0.47392" />
      <inertia
        ixx="0.00093237"
        ixy="-1.0052E-05"
        ixz="0.00048929"
        iyy="0.0012859"
        iyz="-1.3286E-05"
        izz="0.00091329" />
    </inertial>
    <visual>
      <origin
        xyz="0 0 0"
        rpy="0 0 0" />
      <geometry>
        <mesh
          filename="package://robotican_description/robot_arms/armadillo_arm_urdf/meshes/shoulder2_link.STL" />
      </geometry>
      <material
        name="">
        <color
          rgba="0.75294 0.75294 0.75294 1" />
      </material>
    </visual>
    <collision>
      <origin
        xyz="0 0 0"
        rpy="0 0 0" />
      <geometry>
        <mesh
          filename="package://robotican_description/robot_arms/armadillo_arm_urdf/meshes/shoulder2_link.STL" />
      </geometry>
    </collision>
  </link>
  <joint
    name="shoulder2_joint"
    type="revolute">
    <origin
      xyz="0.029998 0 0.264"
      rpy="0 0 0" />
    <parent
      link="shoulder1_link" />
    <child
      link="shoulder2_link" />
    <axis
      xyz="0 1 0" />
    <limit
      effort="25.3"
      lower="-0.65"
      upper="2.3522"
      velocity="3.455751915" />
  </joint>
  <link
    name="rotation2_link">
 <inertial>
      <origin
        xyz="0.018641 0.003816 0.018634"
        rpy="0 0 0" />
      <mass
        value="0.1635" />
      <inertia
        ixx="0.00012408"
        ixy="2.4076E-06"
        ixz="1.7225E-05"
        iyy="8.0775E-05"
        iyz="2.4119E-06"
        izz="0.00012412" />
    </inertial>
    <visual>
      <origin
        xyz="0 0 0"
        rpy="0 0 0" />
      <geometry>
        <mesh
          filename="package://robotican_description/robot_arms/armadillo_arm_urdf/meshes/rotation2_link.STL" />
      </geometry>
      <material
        name="">
        <color
          rgba="0.79216 0.81961 0.93333 1" />
      </material>
    </visual>
    <collision>
      <origin
        xyz="0 0 0"
        rpy="0 0 0" />
      <geometry>
        <mesh
          filename="package://robotican_description/robot_arms/armadillo_arm_urdf/meshes/rotation2_link.STL" />
      </geometry>
    </collision>
  </link>
  <joint
    name="rotation2_joint"
    type="revolute">
    <origin
      xyz="0.13824 0.006 0.18067"
      rpy="0 0 0" />
    <parent
      link="shoulder2_link" />
    <child
      link="rotation2_link" />
    <axis
      xyz="0 0 1" />
    <limit
      effort="25.3"
      lower="-3.14"
      upper="3.14"
      velocity="3.455751915" />
  </joint>
  <link
    name="shoulder3_link">
  <inertial>
      <origin
        xyz="0.049277 0.012748 0.049277"
        rpy="0 0 0" />
      <mass
        value="0.15954" />
      <inertia
        ixx="0.00012881"
        ixy="-3.9839E-06"
        ixz="5.3169E-05"
        iyy="0.00015335"
        iyz="-3.9839E-06"
        izz="0.00012881" />
    </inertial>
    <visual>
      <origin
        xyz="0 0 0"
        rpy="0 0 0" />
      <geometry>
        <mesh
          filename="package://robotican_description/robot_arms/armadillo_arm_urdf/meshes/shoulder3_link.STL" />
      </geometry>
      <material
        name="">
        <color
          rgba="0.75294 0.75294 0.75294 1" />
      </material>
    </visual>
    <collision>
      <origin
        xyz="0 0 0"
        rpy="0 0 0" />
      <geometry>
        <mesh
          filename="package://robotican_description/robot_arms/armadillo_arm_urdf/meshes/shoulder3_link.STL" />
      </geometry>
    </collision>
  </link>
  <joint
    name="shoulder3_joint"
    type="revolute">
    <origin
      xyz="0.022981 -0.006 0.022981"
      rpy="0 0 0" />
    <parent
      link="rotation2_link" />
    <child
      link="shoulder3_link" />
    <axis
      xyz="0 1 0" />
    <limit
      effort="5.1"
      lower="-1.57"
      upper="1.57"
      velocity="3.455751915" />
  </joint>
  <link
    name="wrist_link">
    <inertial>
      <origin
        xyz="0.024492 -8.9152E-11 0.025256"
        rpy="0 0 0" />
      <mass
        value="0.098822" />
      <inertia
        ixx="6.2194E-05"
        ixy="2.1384E-12"
        ixz="3.1204E-06"
        iyy="3.364E-05"
        iyz="-6.2302E-12"
        izz="6.5471E-05" />
    </inertial>
    <visual>
      <origin
        xyz="0 0 0"
        rpy="0 0 0" />
      <geometry>
        <mesh
          filename="package://robotican_description/robot_arms/armadillo_arm_urdf/meshes/wrist_link.STL" />
      </geometry>
      <material
        name="">
        <color
          rgba="0.79216 0.81961 0.93333 1" />
      </material>
    </visual>
    <collision>
      <origin
        xyz="0 0 0"
        rpy="0 0 0" />
      <geometry>
        <mesh
          filename="package://robotican_description/robot_arms/armadillo_arm_urdf/meshes/wrist_link.STL" />
      </geometry>
    </collision>
  </link>
  <joint
    name="wrist_joint"
    type="revolute">
    <origin
      xyz="0.082731 0.012 0.082731"
      rpy="0 0 0" />
    <parent
      link="shoulder3_link" />
    <child
      link="wrist_link" />
    <axis
      xyz="0 0 1" />
    <limit
      effort="5.1"
      lower="-3.14"
      upper="3.14"
      velocity="3.455751915" />
  </joint>
  <link
    name="left_finger_link">
    <inertial>
      <origin
        xyz="0.010673 -0.006351 0.010673"
        rpy="0 0 0" />
      <mass
        value="0.017607" />
      <inertia
        ixx="1.0362E-05"
        ixy="2.1712E-06"
        ixz="4.4332E-06"
        iyy="1.7314E-05"
        iyz="2.1712E-06"
        izz="1.0362E-05" />
    </inertial>
    <visual>
      <origin
        xyz="0 0 0"
        rpy="0 0 0" />
      <geometry>
        <mesh
          filename="package://robotican_description/robot_arms/armadillo_arm_urdf/meshes/left_finger_link.STL" />
      </geometry>
      <material
        name="">
        <color
          rgba="0.86667 0.9098 1 1" />
      </material>
    </visual>
    <collision>
      <origin
        xyz="0 0 0"
        rpy="0 0 0" />
      <geometry>
        <mesh
          filename="package://robotican_description/robot_arms/armadillo_arm_urdf/meshes/left_finger_link.STL" />
      </geometry>
    </collision>
  </link>
  <joint
    name="left_finger_joint"
    type="revolute">
    <origin
   xyz="0.045432 0.049 0.045432"
      rpy="0 0 0" />
    <parent
      link="wrist_link" />
    <child
      link="left_finger_link" />
    <axis
           xyz="-0.70711 0 0.70711" />
    <limit
      effort="3.1"
      lower="-0.4"
      upper="1.0"
      velocity="7.016223585" />
  </joint>
  <link
    name="right_finger_link">
    <inertial>
      <origin
        xyz="0.010673 0.006351 0.010673"
        rpy="0 0 0" />
      <mass
        value="0.017607" />
      <inertia
        ixx="1.0362E-05"
        ixy="-2.1712E-06"
        ixz="4.4332E-06"
        iyy="1.7314E-05"
        iyz="-2.1712E-06"
        izz="1.0362E-05" />
    </inertial>
    <visual>
      <origin
        xyz="0 0 0"
        rpy="0 0 0" />
      <geometry>
        <mesh
          filename="package://robotican_description/robot_arms/armadillo_arm_urdf/meshes/right_finger_link.STL" />
      </geometry>
      <material
        name="">
        <color
          rgba="0.86667 0.9098 1 1" />
      </material>
    </visual>
    <collision>
      <origin
        xyz="0 0 0"
        rpy="0 0 0" />
      <geometry>
        <mesh
          filename="package://robotican_description/robot_arms/armadillo_arm_urdf/meshes/right_finger_link.STL" />
      </geometry>
    </collision>
  </link>
  <joint
    name="right_finger_joint"
    type="revolute">
    <origin
       xyz="0.045432 -0.049 0.045432"
      rpy="0 0 0" />
    <parent
      link="wrist_link" />
    <child
      link="right_finger_link" />
    <axis
      xyz="-0.70711 0 0.70711" />
    <limit
      effort="3.1"
      lower="-1.0"
      upper="0.4"
      velocity="7.016223585" />
  </joint>
  <link
    name="f200_optical_link">
    <inertial>
      <origin
        xyz="1.7297E-09 -0.0057087 -0.016076"
        rpy="0 0 0" />
      <mass
        value="0.092188" />
      <inertia
        ixx="2.6617E-05"
        ixy="-3.0698E-11"
        ixz="3.8544E-11"
        iyy="0.00013594"
        iyz="3.1747E-06"
        izz="0.00012497" />
    </inertial>
    <visual>
      <origin
        xyz="0 0 0"
        rpy="0 0 0" />
      <geometry>
        <mesh
          filename="package://robotican_description/robot_arms/armadillo_arm_urdf/meshes/f200_optical_link.STL" />
      </geometry>
      <material
        name="">
        <color
          rgba="0.79216 0.81961 0.93333 1" />
      </material>
    </visual>
    <collision>
      <origin
        xyz="0 0 0"
        rpy="0 0 0" />
      <geometry>
        <mesh
          filename="package://robotican_description/robot_arms/armadillo_arm_urdf/meshes/f200_optical_link.STL" />
      </geometry>
    </collision>
  </link>
  <joint
    name="f200_optical_joint"
    type="fixed">
    <origin
      xyz="-0.015343 0 0.07453"
      rpy="0 0 -1.5708" />
    <parent
      link="wrist_link" />
    <child
      link="f200_optical_link" />
    <axis
      xyz="0 0 0" />
  </joint>
</robot>
