<robot
  name="h_arm_urdf">
  <link
    name="arm_base_link">
    <inertial>
      <origin
        xyz="-0.025341 -0.00015693 0.00087354"
        rpy="0 0 0" />
      <mass
        value="1.6075" />
      <inertia
        ixx="0.0079143"
        ixy="-1.2323E-06"
        ixz="9.2385E-05"
        iyy="0.0053506"
        iyz="-7.6719E-06"
        izz="0.0072753" />
    </inertial>
    <visual>
      <origin
        xyz="0 0 0"
        rpy="0 0 0" />
      <geometry>
        <mesh
          filename="package://robotican_description/robot_arms/h_arm_urdfV3/meshes/arm_base_link.STL" />
      </geometry>
      <material
        name="">
        <color
          rgba="0.64706 0.61961 0.58824 1" />
      </material>
    </visual>
    <collision>
      <origin
        xyz="0 0 0"
        rpy="0 0 0" />
      <geometry>
        <mesh
          filename="package://robotican_description/robot_arms/h_arm_urdfV3/meshes/arm_base_link.STL" />
      </geometry>
    </collision>
  </link>
  <link
    name="arm_rotation1_link">
    <inertial>
      <origin
        xyz="-3.5191E-10 0.0073117 0.067899"
        rpy="0 0 0" />
      <mass
        value="0.35317" />
      <inertia
        ixx="0.00055596"
        ixy="9.2617E-12"
        ixz="9.2232E-12"
        iyy="0.00016945"
        iyz="6.1918E-06"
        izz="0.00055286" />
    </inertial>
    <visual>
      <origin
        xyz="0 0 0"
        rpy="0 0 0" />
      <geometry>
        <mesh
          filename="package://robotican_description/robot_arms/h_arm_urdfV3/meshes/arm_rotation1_link.STL" />
      </geometry>
      <material
        name="">
        <color
          rgba="0.89804 0.91765 0.92941 1" />
      </material>
    </visual>
    <collision>
      <origin
        xyz="0 0 0"
        rpy="0 0 0" />
      <geometry>
        <mesh
          filename="package://robotican_description/robot_arms/h_arm_urdfV3/meshes/arm_rotation1_link.STL" />
      </geometry>
    </collision>
  </link>
  <joint
    name="arm_rotation1_joint"
    type="revolute">
    <origin
      xyz="0.027 0 0.033"
      rpy="0 0 0" />
    <parent
      link="arm_base_link" />
    <child
      link="arm_rotation1_link" />
    <axis
      xyz="0 0 1" />
    <limit
      effort="0"
      velocity="0"
      lower="-1.57"
      upper="1.57"
     />
  </joint>
  <link
    name="arm_shoulder1_link">
    <inertial>
      <origin
        xyz="0.01628 -0.032683 0.20044"
        rpy="0 0 0" />
      <mass
        value="0.52217" />
      <inertia
        ixx="0.00437"
        ixy="-9.87E-07"
        ixz="0.00053636"
        iyy="0.0041046"
        iyz="-4.3615E-05"
        izz="0.00082919" />
    </inertial>
    <visual>
      <origin
        xyz="0 0 0"
        rpy="0 0 0" />
      <geometry>
        <mesh
          filename="package://robotican_description/robot_arms/h_arm_urdfV3/meshes/arm_shoulder1_link.STL" />
      </geometry>
      <material
        name="">
        <color
          rgba="0.75294 0.75294 0.75294 1" />
      </material>
    </visual>
    <collision>
      <origin
        xyz="0 0 0"
        rpy="0 0 0" />
      <geometry>
        <mesh
          filename="package://robotican_description/robot_arms/h_arm_urdfV3/meshes/arm_shoulder1_link.STL" />
      </geometry>
    </collision>
  </link>
  <joint
    name="arm_shoulder1_joint"
    type="revolute">
    <origin
      xyz="0 0.039 0.069"
      rpy="0 0 0" />
    <parent
      link="arm_rotation1_link" />
    <child
      link="arm_shoulder1_link" />
    <axis
      xyz="0 1 0" />
    <limit
      lower="0"
      upper="1.57"
      effort="0"
      velocity="0" />
  </joint>
  <link
    name="arm_shoulder2_link">
    <inertial>
      <origin
        xyz="-0.029807 -0.020675 0.12921"
        rpy="0 0 0" />
      <mass
        value="0.44964" />
      <inertia
        ixx="0.0013957"
        ixy="2.2944E-06"
        ixz="-9.6791E-06"
        iyy="0.0013155"
        iyz="-1.6943E-05"
        izz="0.0003579" />
    </inertial>
    <visual>
      <origin
        xyz="0 0 0"
        rpy="0 0 0" />
      <geometry>
        <mesh
          filename="package://robotican_description/robot_arms/h_arm_urdfV3/meshes/arm_shoulder2_link.STL" />
      </geometry>
      <material
        name="">
        <color
          rgba="0.79216 0.81961 0.93333 1" />
      </material>
    </visual>
    <collision>
      <origin
        xyz="0 0 0"
        rpy="0 0 0" />
      <geometry>
        <mesh
          filename="package://robotican_description/robot_arms/h_arm_urdfV3/meshes/arm_shoulder2_link.STL" />
      </geometry>
    </collision>
  </link>
  <joint
    name="arm_shoulder2_joint"
    type="revolute">
    <origin
      xyz="0.029998 -0.012 0.264"
      rpy="0 0.7853981634 0" />
    <parent
      link="arm_shoulder1_link" />
    <child
      link="arm_shoulder2_link" />
    <axis
      xyz="0 1 0" />
    <limit
      lower="-0.65"
      upper="2.3522"
      effort="0"
      velocity="0" />
  </joint>
  <link
    name="arm_rotation2_link">
    <inertial>
      <origin
        xyz="1.2931E-08 0.0043427 0.097839"
        rpy="0 0 0" />
      <mass
        value="0.14367" />
      <inertia
        ixx="0.00010361"
        ixy="-8.012E-11"
        ixz="2.2317E-12"
        iyy="4.3409E-05"
        iyz="1.1487E-06"
        izz="0.00010218" />
    </inertial>
    <visual>
      <origin
        xyz="0 0 0"
        rpy="0 0 0" />
      <geometry>
        <mesh
          filename="package://robotican_description/robot_arms/h_arm_urdfV3/meshes/arm_rotation2_link.STL" />
      </geometry>
      <material
        name="">
        <color
          rgba="0.79216 0.81961 0.93333 1" />
      </material>
    </visual>
    <collision>
      <origin
        xyz="0 0 0"
        rpy="0 0 0" />
      <geometry>
        <mesh
          filename="package://robotican_description/robot_arms/h_arm_urdfV3/meshes/arm_rotation2_link.STL" />
      </geometry>
    </collision>
  </link>
  <joint
    name="arm_rotation2_joint"
    type="revolute">
    <origin
      xyz="-0.03 -0.021 0.159"
      rpy="0 0 0" />
    <parent
      link="arm_shoulder2_link" />
    <child
      link="arm_rotation2_link" />
    <axis
      xyz="0 0 1" />
    <limit
      lower="-3.14"
      upper="3.14"
      effort="0"
      velocity="0" />
  </joint>
  <link
    name="arm_shoulder3_link">
    <inertial>
      <origin
        xyz="3.9349E-11 -0.044252 0.069689"
        rpy="0 0 0" />
      <mass
        value="0.15954" />
      <inertia
        ixx="0.00018198"
        ixy="2.101E-13"
        ixz="-2.3374E-13"
        iyy="0.00015335"
        iyz="-5.6341E-06"
        izz="7.5641E-05" />
    </inertial>
    <visual>
      <origin
        xyz="0 0 0"
        rpy="0 0 0" />
      <geometry>
        <mesh
          filename="package://robotican_description/robot_arms/h_arm_urdfV3/meshes/arm_shoulder3_link.STL" />
      </geometry>
      <material
        name="">
        <color
          rgba="0.75294 0.75294 0.75294 1" />
      </material>
    </visual>
    <collision>
      <origin
        xyz="0 0 0"
        rpy="0 0 0" />
      <geometry>
        <mesh
          filename="package://robotican_description/robot_arms/h_arm_urdfV3/meshes/arm_shoulder3_link.STL" />
      </geometry>
    </collision>
  </link>
  <joint
    name="arm_shoulder3_joint"
    type="revolute">
    <origin
      xyz="0 0.051 0.099"
      rpy="0 0 0" />
    <parent
      link="arm_rotation2_link" />
    <child
      link="arm_shoulder3_link" />
    <axis
      xyz="0 1 0" />
    <limit
      lower="-1.57"
      upper="1.57"
      effort="0"
      velocity="0" />
  </joint>
  <link
    name="arm_wrist_link">
    <inertial>
      <origin
        xyz="2.0891E-05 6.5048E-10 0.030365"
        rpy="0 0 0" />
      <mass
        value="0.70734" />
      <inertia
        ixx="0.00048369"
        ixy="3.6682E-12"
        ixz="-3.0001E-06"
        iyy="0.00020635"
        iyz="5.4223E-12"
        izz="0.00043266" />
    </inertial>
    <visual>
      <origin
        xyz="0 0 0"
        rpy="0 0 0" />
      <geometry>
        <mesh
          filename="package://robotican_description/robot_arms/h_arm_urdfV3/meshes/arm_wrist_link.STL" />
      </geometry>
      <material
        name="">
        <color
          rgba="0.86667 0.9098 1 1" />
      </material>
    </visual>
    <collision>
      <origin
        xyz="0 0 0"
        rpy="0 0 0" />
      <geometry>
        <mesh
          filename="package://robotican_description/robot_arms/h_arm_urdfV3/meshes/arm_wrist_link.STL" />
      </geometry>
    </collision>
  </link>
  <joint
    name="arm_wrist_joint"
    type="revolute">
    <origin
      xyz="0 -0.045 0.123"
      rpy="0 0 0" />
    <parent
      link="arm_shoulder3_link" />
    <child
      link="arm_wrist_link" />
    <axis
      xyz="0 0 1" />
    <limit
      lower="-3.14"
      upper="3.14"
      effort="0"
      velocity="0" />
  </joint>
 <link
    name="gripper_r_link">
    <inertial>
      <origin
        xyz="-2.7756E-17 0.014873 0.033361"
        rpy="0 0 0" />
      <mass
        value="0.011198" />
      <inertia
        ixx="9.7735E-06"
        ixy="-9.7742E-22"
        ixz="9.8678E-21"
        iyy="1.1665E-05"
        iyz="7.8401E-07"
        izz="3.3484E-06" />
    </inertial>
    <visual>
      <origin
        xyz="0 0.02471 0.02073"
        rpy="0 0 0" />
      <geometry>
        <mesh
          filename="package://robotican_description/robot_arms/h_arm_urdfV3/meshes/gripper_r_link.STL" />
      </geometry>
      <material
        name="">
        <color
          rgba="0.86667 0.9098 1 1" />
      </material>
    </visual>
    <collision>
      <origin
        xyz="0 0 0"
        rpy="0 0 0" />
      <geometry>
        <mesh
          filename="package://robotican_description/robot_arms/h_arm_urdfV3/meshes/gripper_r_link.STL" />
      </geometry>
    </collision>
  </link>
  <joint
    name="gripper_r_joint"
    type="revolute">
    <origin
      xyz="0 0.021 0.04225"
      rpy="0 0 0" />
    <parent
      link="arm_wrist_link" />
    <child
      link="gripper_r_link" />
    <axis
      xyz="1 0 0" />
    <limit
      lower="-1.0"
      upper="0.4"
      effort="0"
      velocity="0" />
  </joint>
  <link
    name="gripper_l_link">
    <inertial>
      <origin
        xyz="-3.6429E-17 -0.014873 0.033361"
        rpy="0 0 0" />
      <mass
        value="0.011198" />
      <inertia
        ixx="9.7735E-06"
        ixy="1.7627E-21"
        ixz="-5.8868E-21"
        iyy="1.1665E-05"
        iyz="-7.8401E-07"
        izz="3.3484E-06" />
    </inertial>
    <visual>
      <origin
        xyz="0 -0.02471 0.02073"
        rpy="0 0 0" />
      <geometry>
        <mesh
          filename="package://robotican_description/robot_arms/h_arm_urdfV3/meshes/gripper_l_link.STL" />
      </geometry>
      <material
        name="">
        <color
          rgba="0.86667 0.9098 1 1" />
      </material>
    </visual>
    <collision>
      <origin
        xyz="0 0 0"
        rpy="0 0 0" />
      <geometry>
        <mesh
          filename="package://robotican_description/robot_arms/h_arm_urdfV3/meshes/gripper_l_link.STL" />
      </geometry>
    </collision>
  </link>
  <joint
    name="gripper_l_joint"
    type="revolute">
    <origin
      xyz="0 -0.021 0.04225"
      rpy="0 0 0" />
    <parent
      link="arm_wrist_link" />
    <child
      link="gripper_l_link" />
    <axis
      xyz="1 0 0" />
    <limit
      lower="-0.4"
      upper="1.0"
      effort="0"
      velocity="0" />
  </joint>
</robot>
